<?xml version="1.0" encoding="utf-8" ?>
<!-- This URDF was automatically created by SolidWorks to URDF Exporter! Originally created by Stephen Brawner (brawner@gmail.com) 
     Commit Version: 1.6.0-4-g7f85cfe  Build Version: 1.6.7995.38578
     For more information, please see http://wiki.ros.org/sw_urdf_exporter -->
<robot name="car2_sld">
    <link name="dummy" />
    <joint name="dummy_joint" type="fixed">
        <parent link="dummy" />
        <child link="base_link" />
    </joint>
    <link name="base_link">
        <inertial>
            <origin xyz="-2.06493424071167E-16 0.0023469386812806 3.58582616688385E-17" rpy="0 0 0" />
            <mass value="164.353963589239" />
            <inertia ixx="4.62640242563695" ixy="-5.95696794414352E-17" ixz="1.08386561915186E-16" iyy="12.6787643815464" iyz="-6.49913957287132E-17" izz="8.10980826342236" />
        </inertial>
        <visual>
            <origin xyz="0 0 0" rpy="0 0 0" />
            <geometry>
                <mesh filename="package://car2_sld/meshes/base_link.STL" />
            </geometry>
            <material name="">
                <color rgba="0.650980392156863 0.619607843137255 0.588235294117647 1" />
            </material>
        </visual>
        <collision>
            <origin xyz="0 0 0" rpy="0 0 0" />
            <geometry>
                <mesh filename="package://car2_sld/meshes/base_link.STL" />
            </geometry>
        </collision>
    </link>
    <link name="wlf_link">
        <inertial>
            <origin xyz="0 0 -0.01" rpy="0 0 0" />
            <mass value="0.409695097954645" />
            <inertia ixx="0.000589790234763875" ixy="3.94485665153874E-36" ixz="0" iyy="0.000589790234763875" iyz="-4.25822828585374E-37" izz="0.00115226746299744" />
        </inertial>
        <visual>
            <origin xyz="0 0 0" rpy="0 0 0" />
            <geometry>
                <mesh filename="package://car2_sld/meshes/wlf_link.STL" />
            </geometry>
            <material name="">
                <color rgba="0.298039215686275 0.298039215686275 0.298039215686275 1" />
            </material>
        </visual>
        <collision>
            <origin xyz="0 0 0" rpy="0 0 0" />
            <geometry>
                <mesh filename="package://car2_sld/meshes/wlf_link.STL" />
            </geometry>
        </collision>
    </link>
    <joint name="wlf_joint" type="continuous">
        <origin xyz="0.325 0.29 -0.02" rpy="1.5708 0 0" />
        <parent link="base_link" />
        <child link="wlf_link" />
        <axis xyz="0 0 1" />
    </joint>
    <link name="wlb_link">
        <inertial>
            <origin xyz="5.55111512312578E-17 -3.46944695195361E-18 -0.01" rpy="0 0 0" />
            <mass value="0.409695097954645" />
            <inertia ixx="0.000589790234763875" ixy="3.94485665153874E-36" ixz="0" iyy="0.000589790234763875" iyz="-4.25822828585374E-37" izz="0.00115226746299744" />
        </inertial>
        <visual>
            <origin xyz="0 0 0" rpy="0 0 0" />
            <geometry>
                <mesh filename="package://car2_sld/meshes/wlb_link.STL" />
            </geometry>
            <material name="">
                <color rgba="0.298039215686275 0.298039215686275 0.298039215686275 1" />
            </material>
        </visual>
        <collision>
            <origin xyz="0 0 0" rpy="0 0 0" />
            <geometry>
                <mesh filename="package://car2_sld/meshes/wlb_link.STL" />
            </geometry>
        </collision>
    </link>
    <joint name="wlb_joint" type="continuous">
        <origin xyz="-0.325 0.29 -0.02" rpy="1.5707963267949 0 0" />
        <parent link="base_link" />
        <child link="wlb_link" />
        <axis xyz="0 0 1" />
    </joint>
    <link name="wrf_link">
        <inertial>
            <origin xyz="0 0 0.01" rpy="0 0 0" />
            <mass value="0.409695097954645" />
            <inertia ixx="0.000589790234763875" ixy="0" ixz="0" iyy="0.000589790234763875" iyz="-5.93792032008049E-37" izz="0.00115226746299744" />
        </inertial>
        <visual>
            <origin xyz="0 0 0" rpy="0 0 0" />
            <geometry>
                <mesh filename="package://car2_sld/meshes/wrf_link.STL" />
            </geometry>
            <material name="">
                <color rgba="0.298039215686275 0.298039215686275 0.298039215686275 1" />
            </material>
        </visual>
        <collision>
            <origin xyz="0 0 0" rpy="0 0 0" />
            <geometry>
                <mesh filename="package://car2_sld/meshes/wrf_link.STL" />
            </geometry>
        </collision>
    </link>
    <joint name="wrf_joint" type="continuous">
        <origin xyz="0.325 -0.29 -0.02" rpy="1.5708 0 0" />
        <parent link="base_link" />
        <child link="wrf_link" />
        <axis xyz="0 0 1" />
    </joint>
    <link name="wrb_link">
        <inertial>
            <origin xyz="5.55111512312578E-17 -3.46944695195361E-18 0.01" rpy="0 0 0" />
            <mass value="0.409695097954645" />
            <inertia ixx="0.000589790234763875" ixy="3.94485665153874E-36" ixz="0" iyy="0.000589790234763875" iyz="-4.25822828585374E-37" izz="0.00115226746299744" />
        </inertial>
        <visual>
            <origin xyz="0 0 0" rpy="0 0 0" />
            <geometry>
                <mesh filename="package://car2_sld/meshes/wrb_link.STL" />
            </geometry>
            <material name="">
                <color rgba="0.298039215686275 0.298039215686275 0.298039215686275 1" />
            </material>
        </visual>
        <collision>
            <origin xyz="0 0 0" rpy="0 0 0" />
            <geometry>
                <mesh filename="package://car2_sld/meshes/wrb_link.STL" />
            </geometry>
        </collision>
    </link>
    <joint name="wrb_joint" type="continuous">
        <origin xyz="-0.325 -0.29 -0.02" rpy="1.5707963267949 0 0" />
        <parent link="base_link" />
        <child link="wrb_link" />
        <axis xyz="0 0 1" />
    </joint>
    <link name="arm1_link">
        <inertial>
            <origin xyz="-2.626980324594E-09 0.222682177900455 -7.63349871720785E-09" rpy="0 0 0" />
            <mass value="1.27500464040644" />
            <inertia ixx="0.0280786277337189" ixy="4.9682425263076E-10" ixz="-7.0713548738614E-11" iyy="0.000601075274789828" iyz="1.91675335098201E-09" izz="0.0280237082431091" />
        </inertial>
        <visual>
            <origin xyz="0 0 0" rpy="0 0 0" />
            <geometry>
                <mesh filename="package://car2_sld/meshes/arm1_link.STL" />
            </geometry>
            <material name="">
                <color rgba="0.796078431372549 0.823529411764706 0.937254901960784 1" />
            </material>
        </visual>
        <collision>
            <origin xyz="0 0 0" rpy="0 0 0" />
            <geometry>
                <mesh filename="package://car2_sld/meshes/arm1_link.STL" />
            </geometry>
        </collision>
    </link>
    <joint name="arm1_joint" type="continuous">
        <origin xyz="0 0 0.03" rpy="1.5707963267949 0 -0.0039754446169783" />
        <parent link="base_link" />
        <child link="arm1_link" />
        <axis xyz="0 1 0" />
    </joint>
    <link name="arm2_link">
        <inertial>
            <origin xyz="2.31823538698883E-08 0.183362257511322 6.06454495335248E-09" rpy="0 0 0" />
            <mass value="0.930153151725561" />
            <inertia ixx="0.00985132876361779" ixy="-3.56435321521848E-09" ixz="1.99674204928501E-10" iyy="0.000394257488232508" iyz="-1.19413355630031E-09" izz="0.00985451975556886" />
        </inertial>
        <visual>
            <origin xyz="0 0 0" rpy="0 0 0" />
            <geometry>
                <mesh filename="package://car2_sld/meshes/arm2_link.STL" />
            </geometry>
            <material name="">
                <color rgba="0.796078431372549 0.823529411764706 0.937254901960784 1" />
            </material>
        </visual>
        <collision>
            <origin xyz="0 0 0" rpy="0 0 0" />
            <geometry>
                <mesh filename="package://car2_sld/meshes/arm2_link.STL" />
            </geometry>
        </collision>
    </link>
    <joint name="arm2_joint" type="continuous">
        <origin xyz="0 0.469999999999997 0" rpy="-3.14159265358979 0 0.576591541595324" />
        <parent link="arm1_link" />
        <child link="arm2_link" />
        <axis xyz="0 0 1" />
    </joint>
    <link name="arm3_link">
        <inertial>
            <origin xyz="1.83880688453542E-16 0.208988752815505 9.39027501589695E-16" rpy="0 0 0" />
            <mass value="1.22106539786534" />
            <inertia ixx="0.0160392787269217" ixy="-1.10409516311388E-17" ixz="0" iyy="0.000521865417021989" iyz="-1.8655900663276E-19" izz="0.0160610185794677" />
        </inertial>
        <visual>
            <origin xyz="0 0 0" rpy="0 0 0" />
            <geometry>
                <mesh filename="package://car2_sld/meshes/arm3_link.STL" />
            </geometry>
            <material name="">
                <color rgba="0.796078431372549 0.823529411764706 0.937254901960784 1" />
            </material>
        </visual>
        <collision>
            <origin xyz="0 0 0" rpy="0 0 0" />
            <geometry>
                <mesh filename="package://car2_sld/meshes/arm3_link.STL" />
            </geometry>
        </collision>
    </link>
    <joint name="arm3_joint" type="continuous">
        <origin xyz="0 0.375000000000002 0" rpy="-3.14159265358979 0 1.33461891451581" />
        <parent link="arm2_link" />
        <child link="arm3_link" />
        <axis xyz="0 0 1" />
    </joint>
    <link name="hand_link">
        <inertial>
            <origin xyz="1.05818132034585E-16 -9.71445146547012E-17 0.0266893668156185" rpy="0 0 0" />
            <mass value="0.0516505006136003" />
            <inertia ixx="3.12636176175129E-06" ixy="1.05805664768393E-18" ixz="1.55197280888424E-19" iyy="0.00015412961839027" iyz="-1.62553398075858E-20" izz="0.000156395138475128" />
        </inertial>
        <visual>
            <origin xyz="0 0 0" rpy="0 0 0" />
            <geometry>
                <mesh filename="package://car2_sld/meshes/hand_link.STL" />
            </geometry>
            <material name="">
                <color rgba="0.796078431372549 0.823529411764706 0.937254901960784 1" />
            </material>
        </visual>
        <collision>
            <origin xyz="0 0 0" rpy="0 0 0" />
            <geometry>
                <mesh filename="package://car2_sld/meshes/hand_link.STL" />
            </geometry>
        </collision>
    </link>
    <joint name="hand_joint" type="continuous">
        <origin xyz="0 0.37831 0" rpy="1.5708 1.5536 3.1416" />
        <parent link="arm3_link" />
        <child link="hand_link" />
        <axis xyz="0 0 1" />
    </joint>
    <link name="finger1_link">
        <inertial>
            <origin xyz="0.0026233 9.7145E-17 0.035" rpy="0 0 0" />
            <mass value="0.00805" />
            <inertia ixx="3.5554E-06" ixy="-2.5808E-22" ixz="-8.5618E-21" iyy="3.3039E-06" iyz="-1.9604E-21" izz="2.851E-07" />
        </inertial>
        <visual>
            <origin xyz="0 0 0" rpy="0 0 0" />
            <geometry>
                <mesh filename="package://car2_sld/meshes/finger1_link.STL" />
            </geometry>
            <material name="">
                <color rgba="0.79608 0.82353 0.93725 1" />
            </material>
        </visual>
        <collision>
            <origin xyz="0 0 0" rpy="0 0 0" />
            <geometry>
                <mesh filename="package://car2_sld/meshes/finger1_link.STL" />
            </geometry>
        </collision>
    </link>
    <joint name="finger1_joint" type="prismatic">
        <origin xyz="-0.092909 0 0.031689" rpy="0 0 3.1416" />
        <parent link="hand_link" />
        <child link="finger1_link" />
        <axis xyz="1 0 0" />
        <limit lower="-0.092" upper="0" effort="0" velocity="0" />
    </joint>
    <link name="finger2_link">
        <inertial>
            <origin xyz="-0.0026233 -1.4572E-16 0.035" rpy="0 0 0" />
            <mass value="0.00805" />
            <inertia ixx="3.5554E-06" ixy="1.9654E-21" ixz="-1.3084E-20" iyy="3.3039E-06" iyz="2.4107E-20" izz="2.851E-07" />
        </inertial>
        <visual>
            <origin xyz="0 0 0" rpy="0 0 0" />
            <geometry>
                <mesh filename="package://car2_sld/meshes/finger2_link.STL" />
            </geometry>
            <material name="">
                <color rgba="0.79608 0.82353 0.93725 1" />
            </material>
        </visual>
        <collision>
            <origin xyz="0 0 0" rpy="0 0 0" />
            <geometry>
                <mesh filename="package://car2_sld/meshes/finger2_link.STL" />
            </geometry>
        </collision>
    </link>
    <joint name="finger2_joint" type="prismatic">
        <origin xyz="0.093125 0 0.031689" rpy="0 0 3.1416" />
        <parent link="hand_link" />
        <child link="finger2_link" />
        <axis xyz="1 0 0" />
        <limit lower="0" upper="0.092" effort="0" velocity="0" />
    </joint>
    <link name="grasping_frame" />
    <joint name="grasping_frame_joint" type="fixed">
        <parent link="hand_link" />
        <child link="grasping_frame" />
        <origin rpy="0 0 0" xyz="0.000108 0 0.031689" />
    </joint>
    <transmission name="trans_wlf_joint">
        <type>transmission_interface/SimpleTransmission</type>
        <joint name="wlf_joint">
            <hardwareInterface>hardware_interface/EffortJointInterface</hardwareInterface>
        </joint>
        <actuator name="wlf_joint_motor">
            <hardwareInterface>hardware_interface/EffortJointInterface</hardwareInterface>
            <mechanicalReduction>1</mechanicalReduction>
        </actuator>
    </transmission>
    <transmission name="trans_wlb_joint">
        <type>transmission_interface/SimpleTransmission</type>
        <joint name="wlb_joint">
            <hardwareInterface>hardware_interface/EffortJointInterface</hardwareInterface>
        </joint>
        <actuator name="wlb_joint_motor">
            <hardwareInterface>hardware_interface/EffortJointInterface</hardwareInterface>
            <mechanicalReduction>1</mechanicalReduction>
        </actuator>
    </transmission>
    <transmission name="trans_wrf_joint">
        <type>transmission_interface/SimpleTransmission</type>
        <joint name="wrf_joint">
            <hardwareInterface>hardware_interface/EffortJointInterface</hardwareInterface>
        </joint>
        <actuator name="wrf_joint_motor">
            <hardwareInterface>hardware_interface/EffortJointInterface</hardwareInterface>
            <mechanicalReduction>1</mechanicalReduction>
        </actuator>
    </transmission>
    <transmission name="trans_wrb_joint">
        <type>transmission_interface/SimpleTransmission</type>
        <joint name="wrb_joint">
            <hardwareInterface>hardware_interface/EffortJointInterface</hardwareInterface>
        </joint>
        <actuator name="wrb_joint_motor">
            <hardwareInterface>hardware_interface/EffortJointInterface</hardwareInterface>
            <mechanicalReduction>1</mechanicalReduction>
        </actuator>
    </transmission>
    <transmission name="trans_arm1_joint">
        <type>transmission_interface/SimpleTransmission</type>
        <joint name="arm1_joint">
            <hardwareInterface>hardware_interface/EffortJointInterface</hardwareInterface>
        </joint>
        <actuator name="arm1_joint_motor">
            <hardwareInterface>hardware_interface/EffortJointInterface</hardwareInterface>
            <mechanicalReduction>1</mechanicalReduction>
        </actuator>
    </transmission>
    <transmission name="trans_arm2_joint">
        <type>transmission_interface/SimpleTransmission</type>
        <joint name="arm2_joint">
            <hardwareInterface>hardware_interface/EffortJointInterface</hardwareInterface>
        </joint>
        <actuator name="arm2_joint_motor">
            <hardwareInterface>hardware_interface/EffortJointInterface</hardwareInterface>
            <mechanicalReduction>1</mechanicalReduction>
        </actuator>
    </transmission>
    <transmission name="trans_arm3_joint">
        <type>transmission_interface/SimpleTransmission</type>
        <joint name="arm3_joint">
            <hardwareInterface>hardware_interface/EffortJointInterface</hardwareInterface>
        </joint>
        <actuator name="arm3_joint_motor">
            <hardwareInterface>hardware_interface/EffortJointInterface</hardwareInterface>
            <mechanicalReduction>1</mechanicalReduction>
        </actuator>
    </transmission>
    <transmission name="trans_hand_joint">
        <type>transmission_interface/SimpleTransmission</type>
        <joint name="hand_joint">
            <hardwareInterface>hardware_interface/EffortJointInterface</hardwareInterface>
        </joint>
        <actuator name="hand_joint_motor">
            <hardwareInterface>hardware_interface/EffortJointInterface</hardwareInterface>
            <mechanicalReduction>1</mechanicalReduction>
        </actuator>
    </transmission>
    <transmission name="trans_finger1_joint">
        <type>transmission_interface/SimpleTransmission</type>
        <joint name="finger1_joint">
            <hardwareInterface>hardware_interface/EffortJointInterface</hardwareInterface>
        </joint>
        <actuator name="finger1_joint_motor">
            <hardwareInterface>hardware_interface/EffortJointInterface</hardwareInterface>
            <mechanicalReduction>1</mechanicalReduction>
        </actuator>
    </transmission>
    <transmission name="trans_finger2_joint">
        <type>transmission_interface/SimpleTransmission</type>
        <joint name="finger2_joint">
            <hardwareInterface>hardware_interface/EffortJointInterface</hardwareInterface>
        </joint>
        <actuator name="finger2_joint_motor">
            <hardwareInterface>hardware_interface/EffortJointInterface</hardwareInterface>
            <mechanicalReduction>1</mechanicalReduction>
        </actuator>
    </transmission>
    <gazebo>
        <plugin name="gazebo_ros_control">
            <robotNamespace>/</robotNamespace>
        </plugin>
    </gazebo>
</robot>

